try {
    const result = errorsOnThree(3);
} catch (err) {
    console.log('Error caught, no action taken');
}